Workbook
Name 技能講習名: #REF!
Name 許可業種: #REF!
Name 血液型: #REF!
Name 職種名: #REF!
Name 特殊健康診断名: #REF!
Name 特別教育名: #REF!
Name 免許資格名: #REF!

Sheet 元請入力データ
B2: 会社情報
D3: 会社名 | E3: 一新建設株式会社
D5: 建設業の許可
D6: 許可業種 | F6: 許可番号 | L6: 許可年月日
D7: 建築 | E7: 工事業 | F7: 知事 | G7: 特定 | H7: 4 | I7: 第 | J7: 3830 | K7: 号 | L7: 令和 | M7: 4 | N7: 年 | O7: 8 | P7: 月 | Q7: 6 | R7: 日
E9: 工事業 | I9: 第 | K9: 号 | L9: 平成 | N9: 年 | P9: 月 | R9: 日
B13: 工事情報
D14: 工事名称 | E14: 加賀中学校外壁改修その他工事
D15: 施工場所 | E15: 足立区加賀二丁目25番22号
D16: 作業所名 | E16: 加賀中学校外壁改修その他工事現場事務所 | M16: ←記載例「新宿●ビル作業所」
D17: 工事内容 | E17: 外壁改修工事一式、塗装改修工事一式、屋上防水改修工事一式、体育科床改修工事一式、その他関連工事一式 | M17: ←●●造、地上●階、地下●階 など
D19: 契約日 | E19: 令和 | F19: 6 | G19: 年 | H19: 6 | I19: 月 | J19: 28 | K19: 日
D21: 工期 | E21: 自：令和 | F21: 6 | G21: 年 | H21: 6 | I21: 月 | J21: 28 | K21: 日
E22: 至：令和 | F22: 7 | G22: 年 | H22: 1 | I22: 月 | J22: 15 | K22: 日
D24: 契約営業所 | E24: 名称 | I24: 住所
D25: 元請契約 | E25: 一新建設株式会社 | I25: 東京都足立区綾瀬4-17-13
D26: 下請契約 | E26: 同上 | I26: 同上
E28: 名称 | I28: 住所
D29: 発注者名 | E29: 足立区長 近藤弥生 | I29: 〒 | J29: 120-8510
I30: 東京都足立区中央本町一丁目17番1号
B33: 施工体制
D34: 発注者の監督員 | E34: 木村 公祐
D36: 現場代理人 | E36: 遠藤 秀則
D38: 監理技術者 | E38: 須藤 一郎 | H38: ←主任技術者
D39: 専任・非選任 | E39: 専任
D40: 資格内容 | E40: 一級建築施工管理技士
D42: 監督員 | H42: ←施工体制を監督する人、設計監理ではない。
D43: 権限及び
D44: 意見申出方法
D46: 専門技術者 | E46: ―
D47: 資格内容 | E47: ―
D48: 担当工事内容 | E48: ―
B51: 保険等加入状況 | D51: ※保険未加入業者を排除するために、元請企業には下請企業の保険加入への指導が建設業法で義務づけられました。
G52: 健康保険 | J52: 厚生年金保険 | N52: 雇用保険
D53: 保険加入の有無 | G53: 加入 | J53: 加入 | N53: 加入
D55: 元請契約 | E55: 営業所の名称 | G55: 一新建設株式会社
G56: 健康保険 | J56: 厚生年金保険 | N56: 雇用保険
E57: 事務所整理記号等 | G57: 31イルム | J57: 31イルム | N57: 13312962352-035
D59: 下請契約 | E59: 営業所の名称 | G59: 同上
G60: 健康保険 | J60: 厚生年金保険 | N60: 雇用保険
...

Sheet 下請入力データ
O1: =TODAY() -> 46049
A2: 一 次 下 請 業 者 | B2: 会社情報
D3: 会社名 | E3: 株式会社雅
D4: 工事内容 | E4: 左官工事 | I4: ←「鉄筋工事」「塗装工事」など
D5: 代表者氏名 | E5: 宮本紘光 | I5: ←「役職」「氏名」
D7: 郵便番号 | E7: ３５９－１１６１ | F7: ←記載例「555-5555」
D8: 住所 | E8: 埼玉県所沢市狭山ケ丘1-2994-1グリーンハイム202
D9: 電話番号 | E9: ０８０ | F9: - | G9: ５１９９ | H9: - | I9: ６９９７
D10: FAX番号 | E10: ０４２ | F10: - | G10: ００８ | H10: - | I10: ３１７６
D12: 建設業の許可
D13: 許可業種 | F13: 許可番号 | L13: 許可年月日
D14: 左官工事 | E14: 工事業 | F14: 大臣 | G14: 一般 | H14: ５ | I14: 第 | J14: 77178 | K14: 号 | L14: 令和 | M14: 6 | N14: 年 | O14: 3 | P14: 月 | Q14: 22 | R14: 日
E16: 工事業 | F16: 大臣 | G16: 一般 | I16: 第 | K16: 号 | L16: 令和 | N16: 年 | P16: 月 | R16: 日
B20: 店社施工体制
D22: 安全衛生推進者 | E22: 宮本紘光 | H22: ←会社の安全担当の人
D24: 雇用管理責任者 | E24: 宮本紘光 | H24: ←会社のえらい人
D26: 専門技術者 | H26: ←通常の工事では空白でOK
D27: 資格内容 | E27: ―左官一級技能士
D28: 担当工事内容 | E28: ―
B31: 現場情報
D32: 契約日 | E32: 令和 | G32: 年 | I32: 月 | K32: 日
D34: 工期 | E34: 自：令和 | G34: 年 | I34: 月 | K34: 日
E35: 至：令和 | G35: 年 | I35: 月 | K35: 日
D37: 現場代理人 | E37: 小俣拓也 | H37: ←職長でOK
D39: 安全衛生責任者 | E39: 小俣拓也 | H39: ←職長でOK
D41: 主任技術者 | E41: 宮本紘光 | H41: ←たいてい職長でOK
D42: 専任・非選任 | E42: 非専任
D43: 資格内容 | E43: 左官一級技能士
B46: 保険等加入状況 | D46: ※保険未加入業者を排除するために、元請企業には下請企業の保険加入への指導が建設業法で義務づけられました。
E47: 健康保険 | H47: 厚生年金保険 | L47: 雇用保険
D48: 保険加入の有無 | E48: 加入 | H48: 加入 | L48: 加入
D50: 営業所の名称 | E50: 株式会社雅
H51: 厚生年金保険 | L51: 雇用保険
D52: 事務所整理記号等 | E52: 土建組合 | H52: 2153 | L52: 1106‐623229-1
B55: その他
D56: 登録基幹技能者名・種類 | E56: ― | L56: ←登録基幹技能者の名前と種類
E57: ※優秀な技能や技術を継承するシステム作りのために「登録●●基幹技能者」という資格が推奨されています
E58: 企業にとっては経営事項審査での加点対象となるようです。
A60: 二 次 下 請 業 者 | B60: 会社情報
D61: 会社名
...

Sheet 一覧
C6: 全建統一様式
C8: 施工体制台帳・再下請負通知書・
C9: 労務安全に関する届出書
C12: 改訂4版補訂版
C13: 平成28年9月2日 改訂
C14: （最新様式データ集）
C17: 【施工体制台帳関係】
C18: 施工体制台帳作成建設工事の通知
C19: 施工体制台帳
C20: 下請負業者編成表
C21: 再下請負通知書（変更届）
C22: 外国人建設就労者建設現場入場届出書
... C47: の様式を「リファルソフト」がデータ化しました

Sheet 通知
B1: 全建統一様式第2号
L3: 年 月 日
B4: 下請負業者の皆さんへ
H5: 【元請負業者】
H6: 会 社 名 | K6: =元請入力データ!E3 -> 一新建設株式会社
H7: 事業所の名称 | K7: =IF(元請入力データ!E16="","",元請入力データ!E16) -> 加賀中学校外壁改修その他工事現場事務所
C9: 施工体制台帳作成建設工事の通知
B12: 当工事は、建設業法（昭和24年法律第100号）第24条の７に基づく施工体制台帳の作成を要する建設工事です。 この建設工事に従事する下請業者の方は、一次、二次等の層次を問わず、その請け負った建設工事を他の建設業 を営む者（建設業の許可を受けていない者を含みます。）に請け負わせたときは、速やかに 次の手続きを実施してください。 なお、一度提出いただいた事項や書類に変更が生じたときも、遅滞なく、変更の年月日を付記して再提出しなければなりません。 ①再下請負通知書の提出 建設業法第24条７第２項の規程により、遅滞なく、建設業法施行規則（昭和24年建設省令第14号） 第14条の4第1項に規程する再下請負通知書により、自社の建設業登録や主任技術者等の選任状況及び再下請負契約がある場合はその状況を、直近上位の注文者を通じて元請負業者に報告されるようお願いします。 一次下請負業者の方は、後次の下請負業者から提出される再下請負通知をとりまとめ、下請負業者編成表とともに提出してください。 ②再下請負業者に対する通知 他に下請負を行わせる場合は、この書面を複写し交付して、「もしさらに他の者に工事を請け負わせたときは、『再下請負通知書』を提出するとともに、関係する後次の下請負業者に対してこの書面の写しの交付が必要である」旨を伝えなければなりません。
B32: なお、当工事の概要は次の通りですが、不明の点は下記の担当者に照会ください。
B33: 元請名 | D33: =元請入力データ!E3 -> 一新建設株式会社
B34: 発注者名 | D34: =IF(元請入力データ!E29="","",元請入力データ!E29) -> 足立区長 近藤弥生
B35: 工事名 | D35: =IF(元請入力データ!E14="","",元請入力データ!E14) -> 加賀中学校外壁改修その他工事
B36: 現場代理人 | D36: =IF(元請入力データ!E36="","",元請入力データ!E36) -> 遠藤 秀則 | H36: 権限及び意見 申出方法 | K36: ・下請負契約に記載の通り ・文章による
B38: 提出先及び 担当者 | D38: =IF(元請入力データ!E36="","",元請入力データ!E36) -> 遠藤 秀則
B39: （注） | C39: 下請負契約の総額が4,000万円（建築一式工事の場合は、6,000万円）以上となり、施工体制台帳の作成を要する工事は、全ての一次下請負人に対して書面により通知するとともに、この書面を作業所の見やすい場所に掲示する（第24条の７）。ただし、公共工事については下請金額の総額にかかわらず施工体制台帳を作成し、全ての一次下請に対して書面により通知するとともに、この書面を作業所の見やすい場所に掲示する。

Sheet 施工台帳
B1: 全建統一様式第3号 | AC1: 令和4年 11月 30日 | BA1: 《下請負人に関する事項》
M2: 施 工 体 制 台 帳 | BA2: 会社名 | BG2: =IF(下請入力データ!E3="","",下請入力データ!E3) -> 株式会社雅 | BV2: 代表者名 | CA2: =IF(下請入力データ!E5="","",下請入力データ!E5) -> 宮本紘光
B4: [会 社 名] | G4: =元請入力データ!E3 -> 一新建設株式会社 | BA4: 住 所 電話番号 | BG4: 〒 | BH4: =IF(下請入力データ!E7="","",下請入力データ!E7) -> ３５９－１１６１
BG5: =IF(下請入力データ!E8="","",下請入力データ!E8) -> 埼玉県所沢市狭山ケ丘1-2994-1グリーンハイム202 | CB5: (TEL | CF5: =IF(下請入力データ!E9="","",下請入力データ!E9) -> ０８０ | CH5: - | CI5: =IF(下請入力データ!G9="","",下請入力データ!G9) -> ５１９９ | CK5: - | CL5: =IF(下請入力データ!I9="","",下請入力データ!I9) -> ６９９７ | CN5: ）
B6: [事業所名] | G6: =元請入力データ!E16 -> 加賀中学校外壁改修その他工事現場事務所 | BA6: 工事名称 及び工事内容 | BG6: =IF(元請入力データ!E14="","",元請入力データ!E14) -> 加賀中学校外壁改修その他工事
BG7: =IF(下請入力データ!E4="","",下請入力データ!E4) -> 左官工事
BA8: 工 期 | BG8: 自 | BJ8: 令和 | BL8: =IF(下請入力データ!F34="","",下請入力データ!F34) | BN8: 年 | BO8: =IF(下請入力データ!H34="","",下請入力データ!H34) | BQ8: 月 | BR8: =IF(下請入力データ!J34="","",下請入力データ!J34) | BT8: 日 | BW8: 契約日 | CD8: 令和 | CF8: =IF(下請入力データ!F32="","",下請入力データ!F32) | CH8: 年 | CI8: =IF(下請入力データ!H32="","",下請入力データ!H32) | CK8: 月 | CL8: =IF(下請入力データ!J32="","",下請入力データ!J32) | CN8: 日
B9: 建設業の 許 可 | H9: 許可業種 | R9: 許 可 番 号 | AF9: 許可（更新）年月日 | BG9: 至 | BJ9: 令和 | BL9: =IF(下請入力データ!F35="","",下請入力データ!F35) | BN9: 年 | BO9: =IF(下請入力データ!H35="","",下請入力データ!H35) | BQ9: 月 | BR9: =IF(下請入力データ!J35="","",下請入力データ!J35) | BT9: 日
H10: =元請入力データ!D7 -> 建築 | O10: 工事業 | R10: 大臣 | U10: 特定 | X10: =元請入力データ!H7 -> 4 | Z10: 第 | AA10: =元請入力データ!J7 -> 3830 | AE10: 号 | AF10: 令和 | AH10: =元請入力データ!M7 -> 4 | AJ10: 年 | AK10: =元請入力データ!O7 -> 8 | AM10: 月 | AN10: =元請入力データ!Q7 -> 6 | AP10: 日
R11: 知事 | U11: 一般 | BA11: 建設業 の許可 | BG11: 施工に必要な許可業種 | BQ11: 許可番号 | CE11: 許可（更新）年月日
H12: =IF(元請入力データ!D9="","",元請入力データ!D9) | O12: 工事業 | R12: 大臣 | U12: 特定 | X12: =IF(元請入力データ!H9="","",元請入力データ!H9) | Z12: 第 | AA12: =IF(元請入力データ!J9="","",元請入力データ!J9) | AE12: 号 | AF12: 令和 | AH12: =IF(元請入力データ!M9="","",元請入力データ!M9) | AJ12: 年 | AK12: =IF(元請入力データ!O9="","",元請入力データ!O9) | AM12: 月 | AN12: =IF(元請入力データ!Q9="","",元請入力データ!Q9) | AP12: 日 | BG12: =IF(下請入力データ!D14="","",下請入力データ!D14) -> 左官工事 | BN12: 工事業 | BQ12: 大臣 | BT12: 特定 | BW12: =IF(下請入力データ!H14="","",下請入力データ!H14) -> ５ | BY12: 第 | BZ12: =IF(下請入力データ!J14="","",下請入力データ!J14) -> 77178 | CD12: 号 | CE12: 令和 | CG12: =IF(下請入力データ!M14="","",下請入力データ!M14) -> 6 | CI12: 年 | CJ12: =IF(下請入力データ!O14="","",下請入力データ!O14) -> 3 | CL12: 月 | CM12: =IF(下請入力データ!Q14="","",下請入力データ!Q14) -> 22 | CO12: 日
R13: 知事 | U13: 一般 | BQ13: 知事 | BT13: 一般
BG14: =IF(下請入力データ!D16="","",下請入力データ!D16) | BN14: 工事業 | BQ14: 大臣 | BT14: 特定 | BW14: =IF(下請入力データ!H16="","",下請入力データ!H16) | BY14: 第 | BZ14: =IF(下請入力データ!J16="","",下請入力データ!J16) | CD14: 号 | CE14: 令和 | CG14: =IF(下請入力データ!M16="","",下請入力データ!M16) | CI14: 年 | CJ14: =IF(下請入力データ!O16="","",下請入力データ!O16) | CL14: 月 | CM14: =IF(下請入力データ!Q16="","",下請入力データ!Q16) | CO14: 日
B15: 工事名称 及び工事内容 | H15: =IF(元請入力データ!E14="","",元請入力データ!E14) -> 加賀中学校外壁改修その他工事 | BQ15: 知事 | BT15: 一般
H16: =IF(元請入力データ!E17="","",元請入力データ!E17) -> 外壁改修工事一式、塗装改修工事一式、屋上防水改修工事一式、体育科床改修工事一式、その他関連工事一式
B17: 発注者名 及び住所 | H17: =IF(元請入力データ!E29="","",元請入力データ!E29) -> 足立区長 近藤弥生 | BA17: 現場代理人名 | BI17: =IF(下請入力データ!E37="","",下請入力データ!E37) -> 小俣拓也 | BV17: 安全衛生責任者名 | CD17: =IF(下請入力データ!E39="","",下請入力データ!E39) -> 小俣拓也
H18: 〒 | J18: =IF(元請入力データ!J29="","",元請入力データ!J29) -> 120-8510 | O18: =IF(元請入力データ!I30="","",元請入力データ!I30) -> 東京都足立区中央本町一丁目17番1号
B19: 工 期 | H19: 自 | K19: 令和 | M19: =IF(元請入力データ!F21="","",元請入力データ!F21) -> 6 | O19: 年 | P19: =IF(元請入力データ!H21="","",元請入力データ!H21) -> 6 | R19: 月 | S19: =IF(元請入力データ!J21="","",元請入力データ!J21) -> 28 | U19: 日 | X19: 契約日 | AE19: 令和 | AG19: =IF(元請入力データ!F19="","",元請入力データ!F19) -> 6 | AI19: 年 | AJ19: =IF(元請入力データ!H19="","",元請入力データ!H19) -> 6 | AL19: 月 | AM19: =IF(元請入力データ!J19="","",元請入力データ!J19) -> 28 | AO19: 日 | BB19: 権限及び意見 申出方法 | BI19: 契約書に記載の通り 文書による | BV19: 安全衛生推進者名 | CD19: =IF(下請入力データ!E22="","",下請入力データ!E22) -> 宮本紘光
H20: 至 | K20: 令和 | M20: =IF(元請入力データ!F22="","",元請入力データ!F22) -> 7 | O20: 年 | P20: =IF(元請入力データ!H22="","",元請入力データ!H22) -> 1 | R20: 月 | S20: =IF(元請入力データ!J22="","",元請入力データ!J22) -> 15 | U20: 日
BA21: ※主任技術者 | BI21: 専任 | BM21: =IF(下請入力データ!E41="","",下請入力データ!E41) -> 宮本紘光 | BV21: 雇用管理責任者名 | CD21: =IF(下請入力データ!E24="","",下請入力データ!E24) -> 宮本紘光
B22: 契 約 営 業 所 | H22: 区 分 | L22: 名 称 | Z22: 住 所 | BI22: 非専任
H23: 元請契約 | L23: =元請入力データ!E25 -> 一新建設株式会社 | Z23: =元請入力データ!I25 -> 東京都足立区綾瀬4-17-13 | BB23: 資格内容 | BI23: =IF(下請入力データ!E43="","",下請入力データ!E43) -> 左官一級技能士 | BV23: ※専門技術者名 | CD23: =下請入力データ!E26 -> 0
H25: 下請契約 | L25: =IF(元請入力データ!E26="","",元請入力データ!E26) -> 同上 | Z25: =IF(元請入力データ!I26="","",元請入力データ!I26) -> 同上 | BW25: 資 格 内 容 | CD25: =下請入力データ!E27 -> ―左官一級技能士
BA26: ※登録基幹技能者名・種類 | BI26: =下請入力データ!E56 -> ―
BW27: 担当工事内容 | CD27: =下請入力データ!E28 -> ―
B28: 発注者の 監 督 名 | G28: =IF(元請入力データ!E34="","",元請入力データ!E34) -> 木村 公祐 | V28: 権限及び 意見申出方法 | AA28: ・請負契約書に記載の通り ・文書による
BA30: 外国人建設就労者の従事の状況(有無) | BJ30: 有 無 | BU30: 外国人技能実習生の従事の状況(有無) | CD30: 有 無
B31: 監督員名 | G31: 四方 健勝 | V31: 権限及び 意見申出方法 | AA31: ・請負契約書に記載の通り ・文書による
B33: 現 場 代理人名 | G33: =IF(元請入力データ!E36="","",元請入力データ!E36) -> 遠藤 秀則 | V33: 権限及び 意見申出方法 | AA33: ・請負契約書に記載の通り ・文書による | BA33: 健康保険 等の加入 状況 | BE33: 保険加入 の有無 | BJ33: 健康保険 | BT33: 厚生年金保険 | CE33: 雇用保険
BJ34: 加入 未加入 適用除外 | BT34: 加入 未加入 適用除外 | CE34: 加入 未加入 適用除外
B35: 監理技術者・ 主任技術者名 | G35: 専任 非専任 | K35: =IF(元請入力データ!E38="","",元請入力データ!E38) -> 須藤 一郎 | V35: 資格内容 | AA35: =IF(元請入力データ!E40="","",元請入力データ!E40) -> 一級建築施工管理技士 | BE35: 事業所 整理記号等 | BJ35: 営業所の名称 | BR35: 健康保険 | BZ35: 厚生年金保険 | CH35: 雇用保険
BJ36: =IF(下請入力データ!E50="","",下請入力データ!E50) -> 株式会社雅 | BR36: =IF(下請入力データ!E52="","",下請入力データ!E52) -> 土建組合 | BZ36: =IF(下請入力データ!H52="","",下請入力データ!H52) -> 2153 | CH36: =IF(下請入力データ!L52="","",下請入力データ!L52) -> 1106‐623229-1
B37: 専 門 技術者名 | G37: ― | V37: 専 門 技術者名 | AA37: ―
C39: 資格内容 | G39: ― | W39: 資格内容 | AA39: ―
C41: 担 当 工事内容 | G41: ― | W41: 担 当 工事内容 | AA41: ―
B44: 外国人建設就労者の従事の状況(有無) | I44: 有 無 | V44: 外国人技能実習生の従事の状況(有無) | AC44: 有 無
B47: 健康保険 等の加入 状況 | F47: 保険加入 の有無 | K47: 健康保険 | V47: 厚生年金保険 | AF47: 雇用保険
K48: 加入 未加入 適用除外 | V48: 加入 未加入 適用除外 | AF48: 加入 未加入 適用除外
F49: 事業所 整理記号 等 | K49: 区分 | O49: 営業所の名称 | V49: 健康保険 | AC49: 厚生年金保険 | AJ49: 雇用保険
K50: 元請契約 | O50: =元請入力データ!G55 -> 一新建設株式会社 | V50: =元請入力データ!G57 -> 31イルム | AC50: =元請入力データ!J57 -> 31イルム | AJ50: =元請入力データ!N57 -> 13312962352-035
...

Sheet 下請編成
B1: 全国統一様式第１号－乙
N2: 令和 年 月 日
F4: 下請負業者編成表
F5: (一次下請負業者＝作成下請負業者)
F7: ガラス | G7: 会 社 名 | J7: =IF(下請入力データ!E3="","",下請入力データ!E3) -> 株式会社雅
G8: 安全衛生責任者 | J8: =IF(下請入力データ!E39="","",下請入力データ!E39) -> 小俣拓也
G9: 主 任 技 術 者 | J9: =IF(下請入力データ!E41="","",下請入力データ!E41) -> 宮本紘光
G10: 専 門 技 術 者 | J10: ―
F11: 工事 | H11: 担当工事内容 | J11: ―
G12: 登録基幹技能者 | J12: ―
F13: 工期 | H13: 令和4年11月20日～令和5年1月9日
B16: (２次下請負業者) | G16: (２次下請負業者) | L16: (２次下請負業者)
B17: ガラス | C17: 会 社 名 | G17: 電気 | H17: 会 社 名 | M17: 会 社 名
C18: 安全衛生責任者 | H18: 安全衛生責任者 | M18: 安全衛生責任者
C19: 主 任 技 術 者 | H19: 主 任 技 術 者 | M19: 主 任 技 術 者
B20: 工事 | C20: 専 門 技 術 者 | E20: ― | G20: 工事 | H20: 専 門 技 術 者 | L20: 工事 | M20: 専 門 技 術 者
D21: 担当工事内容 | E21: ― | I21: 担当工事内容 | N21: 担当工事内容
B22: 工期 | D22: 令和4年11月20日～ 令和5年1月9日 | G22: 工期 | I22: 年 月 日～ 年 月 日 | L22: 工期 | N22: 年 月 日～ 年 月 日
B25: (３次下請負業者) | G25: (３次下請負業者) | L25: (３次下請負業者)
C26: 会 社 名 | H26: 会 社 名 | J26: =IF(下請入力データ!E119="","",下請入力データ!E119) | M26: 会 社 名
C27: 安全衛生責任者 | H27: 安全衛生責任者 | J27: =IF(下請入力データ!E155="","",下請入力データ!E155) | M27: 安全衛生責任者
C28: 主 任 技 術 者 | H28: 主 任 技 術 者 | J28: =IF(下請入力データ!E157="","",下請入力データ!E157) | M28: 主 任 技 術 者
B29: 工事 | C29: 専 門 技 術 者 | G29: 工事 | H29: 専 門 技 術 者 | L29: 工事 | M29: 専 門 技 術 者
D30: 担当工事内容 | I30: 担当工事内容 | N30: 担当工事内容
B31: 工期 | D31: 年 月 日～ 年 月 日 | G31: 工期 | I31: 年 月 日～ 年 月 日 | L31: 工期 | N31: 年 月 日～ 年 月 日
B34: (４次下請負業者) | G34: (４次下請負業者) | L34: (４次下請負業者)
C35: 会 社 名 | H35: 会 社 名 | M35: 会 社 名
C36: 安全衛生責任者 | H36: 安全衛生責任者 | M36: 安全衛生責任者
C37: 主 任 技 術 者 | H37: 主 任 技 術 者 | M37: 主 任 技 術 者
B38: 工事 | C38: 専 門 技 術 者 | G38: 工事 | H38: 専 門 技 術 者 | L38: 工事 | M38: 専 門 技 術 者
D39: 担当工事内容 | I39: 担当工事内容 | N39: 担当工事内容
B40: 工期 | D40: 年 月 日～ 年 月 日 | G40: 工期 | I40: 年 月 日～ 年 月 日 | L40: 工期 | N40: 年 月 日～ 年 月 日
B41: (記入要領) １．一次下請負業者は、二次下請負業者以下の業者から提出された「届出書」(様式１号－甲)に基づいて
B42: 本表を作成の上、元請に届出ること。
B43: ２．この下請負業者編成表でまとめきれない場合には、本様式をコピーするなどして適宜使用すること。
B44: ３．二次下請業者を使用しない場合は、この書類は提出不要。

Sheet 再下請負
B1: 全建統一様式第1号-甲
AA2: 令和 4年 11月 30日
N4: 再下請負通知書（変更届） | BB4: 《再下請負関係》 | BK4: 再下請負業者及び再下請負契約関係について次の通り報告いたします。
BB6: 会社名 | BH6: =下請入力データ!E61 -> 0 | BW6: 代表者名 | CB6: =下請入力データ!E63 -> 0
B7: 直近上位の | G7: =元請入力データ!E3 -> 一新建設株式会社 | V7: 【報告下請負業者】
B8: 注文者名 | Z8: 〒 | AB8: =IF(下請入力データ!E7="","",下請入力データ!E7) -> ３５９－１１６１ | BB8: 住 所 電話番号 | BH8: 〒 | BJ8: =下請入力データ!E65 -> 0
B9: 現場代理人名 | G9: =IF(元請入力データ!E36="","",元請入力データ!E36) -> 遠藤 秀則 | S9: 殿 | V9: 住 所 | AA9: =IF(下請入力データ!E8="","",下請入力データ!E8) -> 埼玉県所沢市狭山ケ丘1-2994-1グリーンハイム202 | BH9: =下請入力データ!E66 -> 0 | BZ9: (TEL | CD9: =IF(下請入力データ!E67="","",下請入力データ!E67) | CG9: - | CH9: =IF(下請入力データ!G67="","",下請入力データ!G67) | CK9: - | CL9: =IF(下請入力データ!I67="","",下請入力データ!I67) | CP9: ）
B10: （所長名） | BB10: 工事名称 及び工事内容 | BH10: =IF(元請入力データ!E14="","",元請入力データ!E14) -> 加賀中学校外壁改修その他工事
AA11: TEL | AE11: =IF(下請入力データ!E9="","",下請入力データ!E9) -> ０８０ | AH11: - | AI11: =IF(下請入力データ!G9="","",下請入力データ!G9) -> ５１９９ | AL11: - | AM11: =IF(下請入力データ!I9="","",下請入力データ!I9) -> ６９９７ | BH11: =IF(下請入力データ!E62="","",下請入力データ!E62)
C12: 元請名称 | H12: =元請入力データ!E3 -> 一新建設株式会社 | AA12: FAX | AE12: =IF(下請入力データ!E10="","",下請入力データ!E10) -> ０４２ | AH12: - | AI12: =IF(下請入力データ!G10="","",下請入力データ!G10) -> ００８ | AL12: - | AM12: =IF(下請入力データ!I10="","",下請入力データ!I10) -> ３１７６ | BB12: 工 期 | BH12: 自 | BK12: 令和 | BM12: =IF(下請入力データ!F92="","",下請入力データ!F92) | BO12: 年 | BP12: =IF(下請入力データ!H92="","",下請入力データ!H92) | BR12: 月 | BS12: =IF(下請入力データ!J92="","",下請入力データ!J92) | BU12: 日 | BX12: 契約日 | CE12: 令和 | CG12: =IF(下請入力データ!F90="","",下請入力データ!F90) | CI12: 年 | CJ12: =IF(下請入力データ!H90="","",下請入力データ!H90) | CL12: 月 | CM12: =IF(下請入力データ!J90="","",下請入力データ!J90) | CO12: 日
U13: 会 社 名 | AA13: =IF(下請入力データ!E3="","",下請入力データ!E3) -> 株式会社雅 | BH13: 至 | BK13: 令和 | BM13: =IF(下請入力データ!F93="","",下請入力データ!F93) | BO13: 年 | BP13: =IF(下請入力データ!H93="","",下請入力データ!H93) | BR13: 月 | BS13: =IF(下請入力データ!J93="","",下請入力データ!J93) | BU13: 日
U15: 代表者名 | AA15: =IF(下請入力データ!E5="","",下請入力データ!E5) -> 宮本紘光 | BB15: 建設業の 許 可 | BH15: 施工に必要な許可業種 | BR15: 許可番号 | CF15: 許可（更新）年月日
B16: ≪自社に関する事項≫ | BH16: =IF(下請入力データ!D72="","",下請入力データ!D72) | BO16: 工事業 | BR16: 大臣 | BU16: 特定 | BX16: =IF(下請入力データ!H72="","",下請入力データ!H72) | BZ16: 第 | CA16: =IF(下請入力データ!J72="","",下請入力データ!J72) | CE16: 号 | CF16: 令和 | CH16: =IF(下請入力データ!M72="","",下請入力データ!M72) | CJ16: 年 | CK16: =IF(下請入力データ!O72="","",下請入力データ!O72) | CM16: 月 | CN16: =IF(下請入力データ!Q72="","",下請入力データ!Q72) | CP16: 日
BR17: 知事 | BU17: 一般
B18: 工事名称 及び工事内容 | H18: =IF(元請入力データ!E14="","",元請入力データ!E14) -> 加賀中学校外壁改修その他工事 | BH18: =IF(下請入力データ!D74="","",下請入力データ!D74) | BO18: 工事業 | BR18: 大臣 | BU18: 特定 | BX18: =IF(下請入力データ!H74="","",下請入力データ!H74) | BZ18: 第 | CA18: =IF(下請入力データ!J74="","",下請入力データ!J74) | CE18: 号 | CF18: 令和 | CH18: =IF(下請入力データ!M74="","",下請入力データ!M74) | CJ18: 年 | CK18: =IF(下請入力データ!O74="","",下請入力データ!O74) | CM18: 月 | CN18: =IF(下請入力データ!Q74="","",下請入力データ!Q74) | CP18: 日
H19: =IF(下請入力データ!E4="","",下請入力データ!E4) -> 左官工事 | BR19: 知事 | BU19: 一般
B20: 工期 | H20: 自 | K20: 令和 | M20: =IF(下請入力データ!F34="","",下請入力データ!F34) | O20: 年 | P20: =IF(下請入力データ!H34="","",下請入力データ!H34) | R20: 月 | S20: =IF(下請入力データ!J34="","",下請入力データ!J34) | U20: 日 | X20: 注文者と の契約日 | AE20: 令和 | AG20: =IF(下請入力データ!F32="","",下請入力データ!F32) | AI20: 年 | AJ20: =IF(下請入力データ!H32="","",下請入力データ!H32) | AL20: 月 | AM20: =IF(下請入力データ!J32="","",下請入力データ!J32) | AO20: 日
H21: 至 | K21: 令和 | M21: =IF(下請入力データ!F35="","",下請入力データ!F35) | O21: 年 | P21: =IF(下請入力データ!H35="","",下請入力データ!H35) | R21: 月 | S21: =IF(下請入力データ!J35="","",下請入力データ!J35) | U21: 日 | BB21: 現場代理人名 | BJ21: =IF(下請入力データ!E95="","",下請入力データ!E95) | BW21: 安全衛生責任者名 | CE21: =IF(下請入力データ!E97="","",下請入力データ!E97)
B22: 建設業の 許 可 | H22: 施工に必要な許可業種 | R22: 許可番号 | AF22: 許可（更新）年月日
H23: =IF(下請入力データ!D14="","",下請入力データ!D14) -> 左官工事 | O23: 工事業 | R23: 大臣 | U23: 特定 | X23: 1 | Z23: 第 | AA23: =IF(下請入力データ!J14="","",下請入力データ!J14) -> 77178 | AE23: 号 | AF23: 令和 | AH23: =IF(下請入力データ!M14="","",下請入力データ!M14) -> 6 | AJ23: 年 | AK23: =IF(下請入力データ!O14="","",下請入力データ!O14) -> 3 | AM23: 月 | AN23: =IF(下請入力データ!Q14="","",下請入力データ!Q14) -> 22 | AP23: 日 | BC23: 権限及び意見 申出方法 | BJ23: 契約書に記載の通り 文書による | BW23: 安全衛生推進者名 | CE23: =IF(下請入力データ!E80="","",下請入力データ!E80)
R24: 知事 | U24: 一般
H25: =IF(下請入力データ!D16="","",下請入力データ!D16) | O25: 工事業 | R25: 大臣 | U25: 特定 | X25: =IF(下請入力データ!H16="","",下請入力データ!H16) | Z25: 第 | AA25: =IF(下請入力データ!J16="","",下請入力データ!J16) | AE25: 号 | AF25: 令和 | AH25: =IF(下請入力データ!M16="","",下請入力データ!M16) | AJ25: 年 | AK25: =IF(下請入力データ!O16="","",下請入力データ!O16) | AM25: 月 | AN25: =IF(下請入力データ!Q16="","",下請入力データ!Q16) | AP25: 日 | BB25: ※主任技術者 | BJ25: 専任 | BN25: =IF(下請入力データ!E99="","",下請入力データ!E99) | BW25: 雇用管理責任者名 | CE25: =IF(下請入力データ!E82="","",下請入力データ!E82)
R26: 知事 | U26: 一般 | BJ26: 非専任
BC27: 資格内容 | BJ27: =IF(下請入力データ!E101="","",下請入力データ!E101) | BW27: ※専門技術者名 | CE27: =下請入力データ!E84 -> 0
B28: 監督員名 | J28: ― | W28: 安全衛生責任者名 | AE28: =IF(下請入力データ!E39="","",下請入力データ!E39) -> 小俣拓也
BX29: 資 格 内 容 | CE29: =下請入力データ!E85 -> 0
C30: 権限及び意見 申出方法 | J30: ― | W30: 安全衛生推進者名 | AE30: =IF(下請入力データ!E22="","",下請入力データ!E22) -> 宮本紘光
BB31: ※登録基幹技能者名・種類 | BJ31: =下請入力データ!E114 -> ― | BX31: 担当工事内容 | CE31: =下請入力データ!E86 -> 0
B32: 現場代理人名 | J32: =IF(下請入力データ!E37="","",下請入力データ!E37) -> 小俣拓也 | W32: 雇用管理責任者名 | AE32: =IF(下請入力データ!E24="","",下請入力データ!E24) -> 宮本紘光
C34: 権限及び意見 申出方法 | J34: 契約書に記載の通り 文書による | W34: ※専門技術者名 | AE34: =下請入力データ!E26 -> 0 | BB34: 外国人建設就労者の従事の状況(有無) | BK34: 有 無 | BV34: 外国人技能実習生の従事の状況(有無) | CE34: 有 無
B36: ※主任技術者名 | J36: 専任 | N36: =IF(下請入力データ!E41="","",下請入力データ!E41) -> 宮本紘光 | X36: 資 格 内 容 | AE36: =下請入力データ!E27 -> ―左官一級技能士
J37: 非専任 | BB37: 健康保険 等の加入 状況 | BF37: 保険加入 の有無 | BK37: 健康保険 | BU37: 厚生年金保険 | CF37: 雇用保険
C38: 資格内容 | J38: =IF(下請入力データ!E43="","",下請入力データ!E43) -> 左官一級技能士 | X38: 担当工事内容 | AE38: =下請入力データ!E28 -> ― | BK38: 加入 未加入 適用除外 | BU38: 加入 未加入 適用除外 | CF38: 加入 未加入 適用除外
BF39: 事業所 整理記号等 | BK39: 営業所の名称 | BS39: 健康保険 | CA39: 厚生年金保険 | CI39: 雇用保険
BK40: =IF(下請入力データ!E108="","",下請入力データ!E108) | BS40: =IF(下請入力データ!E110="","",下請入力データ!E110) | CA40: =IF(下請入力データ!H110="","",下請入力データ!H110) | CI40: =IF(下請入力データ!L110="","",下請入力データ!L110)
B41: ※登録基幹技能者名・種類 | J41: =下請入力データ!E56 -> ―
B44: 外国人建設就労者の従事の状況(有無) | K44: 有 無 | V44: 外国人技能実習生の従事の状況(有無) | AE44: 有 無
B47: 健康保険 等の加入 状況 | F47: 保険加入 の有無 | K47: 健康保険 | U47: 厚生年金保険 | AF47: 雇用保険
K48: 加入 未加入 適用除外 | U48: 加入 未加入 適用除外 | AF48: 加入 未加入 適用除外
F49: 事業所 整理記号等 | K49: 営業所の名称 | S49: 健康保険 | AA49: 厚生年金保険 | AI49: 雇用保険
...

Sheet 再下請負 (2)
B1: 全建統一様式第1号-甲
AA2: 年 月 日
N4: 再下請負通知書（変更届） | BB4: 《再下請負関係》 | BK4: 再下請負業者及び再下請負契約関係について次の通り報告いたします。
BB6: 会社名 | BH6: =IF(下請入力データ!E119="","",下請入力データ!E119) | BW6: 代表者名 | CB6: =IF(下請入力データ!E121="","",下請入力データ!E121)
B7: 直近上位の | G7: =IF(下請入力データ!E3="","",下請入力データ!E3) -> 株式会社雅 | V7: 【報告下請負業者】
B8: 注文者名 | Z8: 〒 | AB8: =IF(下請入力データ!E65="","",下請入力データ!E65) | BB8: 住 所 電話番号 | BH8: 〒 | BJ8: =IF(下請入力データ!E123="","",下請入力データ!E123)
B9: 現場代理人名 | G9: =IF(下請入力データ!E37="","",下請入力データ!E37) -> 小俣拓也 | S9: 殿 | V9: 住 所 | AA9: =IF(下請入力データ!E66="","",下請入力データ!E66) | BH9: =IF(下請入力データ!E124="","",下請入力データ!E124) | BZ9: (TEL | CD9: =IF(下請入力データ!E125="","",下請入力データ!E125) | CG9: - | CH9: =IF(下請入力データ!G125="","",下請入力データ!G125) | CK9: - | CL9: =IF(下請入力データ!I125="","",下請入力データ!I125) | CP9: ）
B10: （所長名） | BB10: 工事名称 及び工事内容 | BH10: =IF(元請入力データ!E14="","",元請入力データ!E14) -> 加賀中学校外壁改修その他工事
AA11: TEL | AE11: =IF(下請入力データ!E67="","",下請入力データ!E67) | AH11: - | AI11: =IF(下請入力データ!G67="","",下請入力データ!G67) | AL11: - | AM11: =IF(下請入力データ!I67="","",下請入力データ!I67) | BH11: =IF(下請入力データ!E120="","",下請入力データ!E120)
C12: 元請名称 | H12: =元請入力データ!E3 -> 一新建設株式会社 | AA12: FAX | AE12: =IF(下請入力データ!E68="","",下請入力データ!E68) | AH12: - | AI12: =IF(下請入力データ!G68="","",下請入力データ!G68) | AL12: - | AM12: =IF(下請入力データ!I68="","",下請入力データ!I68) | BB12: 工 期 | BH12: 自 | BK12: 令和 | BM12: =IF(下請入力データ!F150="","",下請入力データ!F150) | BO12: 年 | BP12: =IF(下請入力データ!H150="","",下請入力データ!H150) | BR12: 月 | BS12: =IF(下請入力データ!J150="","",下請入力データ!J150) | BU12: 日 | BX12: 契約日 | CE12: 令和 | CG12: =IF(下請入力データ!F148="","",下請入力データ!F148) | CI12: 年 | CJ12: =IF(下請入力データ!H148="","",下請入力データ!H148) | CL12: 月 | CM12: =IF(下請入力データ!J148="","",下請入力データ!J148) | CO12: 日
U13: 会 社 名 | AA13: =IF(下請入力データ!E61="","",下請入力データ!E61) | BH13: 至 | BK13: 令和 | BM13: =IF(下請入力データ!F151="","",下請入力データ!F151) | BO13: 年 | BP13: =IF(下請入力データ!H151="","",下請入力データ!H151) | BR13: 月 | BS13: =IF(下請入力データ!J151="","",下請入力データ!J151) | BU13: 日
U15: 代表者名 | AA15: =IF(下請入力データ!E63="","",下請入力データ!E63) | BB15: 建設業の 許 可 | BH15: 施工に必要な許可業種 | BR15: 許可番号 | CF15: 許可（更新）年月日
B16: ≪自社に関する事項≫ | BH16: =IF(下請入力データ!D130="","",下請入力データ!D130) | BO16: 工事業 | BR16: 大臣 | BU16: 特定 | BX16: =IF(下請入力データ!H130="","",下請入力データ!H130) | BZ16: 第 | CA16: =IF(下請入力データ!J130="","",下請入力データ!J130) | CE16: 号 | CF16: 令和 | CH16: =IF(下請入力データ!M130="","",下請入力データ!M130) | CJ16: 年 | CK16: =IF(下請入力データ!O130="","",下請入力データ!O130) | CM16: 月 | CN16: =IF(下請入力データ!Q130="","",下請入力データ!Q130) | CP16: 日
BR17: 知事 | BU17: 一般
B18: 工事名称 及び工事内容 | H18: =IF(元請入力データ!E14="","",元請入力データ!E14) -> 加賀中学校外壁改修その他工事 | BH18: =IF(下請入力データ!D132="","",下請入力データ!D132) | BO18: 工事業 | BR18: 大臣 | BU18: 特定 | BX18: =IF(下請入力データ!H132="","",下請入力データ!H132) | BZ18: 第 | CA18: =IF(下請入力データ!J132="","",下請入力データ!J132) | CE18: 号 | CF18: 令和 | CH18: =IF(下請入力データ!M132="","",下請入力データ!M132) | CJ18: 年 | CK18: =IF(下請入力データ!O132="","",下請入力データ!O132) | CM18: 月 | CN18: =IF(下請入力データ!Q132="","",下請入力データ!Q132) | CP18: 日
H19: =IF(下請入力データ!E62="","",下請入力データ!E62) | BR19: 知事 | BU19: 一般
B20: 工期 | H20: 自 | K20: 令和 | M20: =IF(下請入力データ!F92="","",下請入力データ!F92) | O20: 年 | P20: =IF(下請入力データ!H92="","",下請入力データ!H92) | R20: 月 | S20: =IF(下請入力データ!J92="","",下請入力データ!J92) | U20: 日 | X20: 注文者と の契約日 | AE20: 令和 | AG20: =IF(下請入力データ!F90="","",下請入力データ!F90) | AI20: 年 | AJ20: =IF(下請入力データ!H90="","",下請入力データ!H90) | AL20: 月 | AM20: =IF(下請入力データ!J90="","",下請入力データ!J90) | AO20: 日
H21: 至 | K21: 令和 | M21: =IF(下請入力データ!F93="","",下請入力データ!F93) | O21: 年 | P21: =IF(下請入力データ!H93="","",下請入力データ!H93) | R21: 月 | S21: =IF(下請入力データ!J93="","",下請入力データ!J93) | U21: 日 | BB21: 現場代理人名 | BJ21: =IF(下請入力データ!E153="","",下請入力データ!E153) | BW21: 安全衛生責任者名 | CE21: =IF(下請入力データ!E155="","",下請入力データ!E155)
B22: 建設業の 許 可 | H22: 施工に必要な許可業種 | R22: 許可番号 | AF22: 許可（更新）年月日
H23: =IF(下請入力データ!D72="","",下請入力データ!D72) | O23: 工事業 | R23: 大臣 | U23: 特定 | X23: =IF(下請入力データ!H72="","",下請入力データ!H72) | Z23: 第 | AA23: =IF(下請入力データ!J72="","",下請入力データ!J72) | AE23: 号 | AF23: 令和 | AH23: =IF(下請入力データ!M72="","",下請入力データ!M72) | AJ23: 年 | AK23: =IF(下請入力データ!O72="","",下請入力データ!O72) | AM23: 月 | AN23: =IF(下請入力データ!Q72="","",下請入力データ!Q72) | AP23: 日 | BC23: 権限及び意見 申出方法 | BJ23: 契約書に記載の通り 文書による | BW23: 安全衛生推進者名 | CE23: =IF(下請入力データ!E138="","",下請入力データ!E138)
R24: 知事 | U24: 一般
H25: =IF(下請入力データ!D74="","",下請入力データ!D74) | O25: 工事業 | R25: 大臣 | U25: 特定 | X25: =IF(下請入力データ!H74="","",下請入力データ!H74) | Z25: 第 | AA25: =IF(下請入力データ!J74="","",下請入力データ!J74) | AE25: 号 | AF25: 令和 | AH25: =IF(下請入力データ!M74="","",下請入力データ!M74) | AJ25: 年 | AK25: =IF(下請入力データ!O74="","",下請入力データ!O74) | AM25: 月 | AN25: =IF(下請入力データ!Q74="","",下請入力データ!Q74) | AP25: 日 | BB25: ※主任技術者 | BJ25: 専任 | BN25: =IF(下請入力データ!E157="","",下請入力データ!E157) | BW25: 雇用管理責任者名 | CE25: =IF(下請入力データ!E140="","",下請入力データ!E140)
R26: 知事 | U26: 一般 | BJ26: 非専任
BC27: 資格内容 | BJ27: =IF(下請入力データ!E159="","",下請入力データ!E159) | BW27: ※専門技術者名 | CE27: =下請入力データ!E142 -> ―
B28: 監督員名 | J28: ― | W28: 安全衛生責任者名 | AE28: =IF(下請入力データ!E97="","",下請入力データ!E97)
BX29: 資 格 内 容 | CE29: =下請入力データ!E143 -> ―
C30: 権限及び意見 申出方法 | J30: ― | W30: 安全衛生推進者名 | AE30: =IF(下請入力データ!E80="","",下請入力データ!E80)
BB31: ※登録基幹技能者名・種類 | BJ31: =下請入力データ!E172 -> ― | BX31: 担当工事内容 | CE31: =下請入力データ!E144 -> ―
B32: 現場代理人名 | J32: =IF(下請入力データ!E95="","",下請入力データ!E95) | W32: 雇用管理責任者名 | AE32: =IF(下請入力データ!E82="","",下請入力データ!E82)
C34: 権限及び意見 申出方法 | J34: 契約書に記載の通り 文書による | W34: ※専門技術者名 | AE34: =下請入力データ!E84 -> 0 | BB34: 外国人建設就労者の従事の状況(有無) | BK34: 有 無 | BV34: 外国人技能実習生の従事の状況(有無) | CE34: 有 無
B36: ※主任技術者名 | J36: 専任 | N36: =IF(下請入力データ!E99="","",下請入力データ!E99) | X36: 資 格 内 容 | AE36: =下請入力データ!E85 -> 0
J37: 非専任 | BB37: 健康保険 等の加入 状況 | BF37: 保険加入 の有無 | BK37: 健康保険 | BU37: 厚生年金保険 | CF37: 雇用保険
C38: 資格内容 | J38: =IF(下請入力データ!E101="","",下請入力データ!E101) | X38: 担当工事内容 | AE38: =下請入力データ!E86 -> 0 | BK38: 加入 未加入 適用除外 | BU38: 加入 未加入 適用除外 | CF38: 加入 未加入 適用除外
BF39: 事業所 整理記号等 | BK39: 営業所の名称 | BS39: 健康保険 | CA39: 厚生年金保険 | CI39: 雇用保険
BK40: =IF(下請入力データ!E166="","",下請入力データ!E166) | BS40: =IF(下請入力データ!E168="","",下請入力データ!E168) | CA40: =IF(下請入力データ!H168="","",下請入力データ!H168) | CI40: =IF(下請入力データ!L168="","",下請入力データ!L168)
B41: ※登録基幹技能者名・種類 | J41: =下請入力データ!E114 -> ―
B44: 外国人建設就労者の従事の状況(有無) | K44: 有 無 | V44: 外国人技能実習生の従事の状況(有無) | AE44: 有 無
B47: 健康保険 等の加入 状況 | F47: 保険加入 の有無 | K47: 健康保険 | U47: 厚生年金保険 | AF47: 雇用保険
K48: 加入 未加入 適用除外 | U48: 加入 未加入 適用除外 | AF48: 加入 未加入 適用除外
F49: 事業所 整理記号等 | K49: 営業所の名称 | S49: 健康保険 | AA49: 厚生年金保険 | AI49: 雇用保険
...

Sheet 外国人
B1: 全建統一様式第１号―甲―別紙
I4: 外国人建設就労者建設現場入場届出書
B5: =IF(元請入力データ!E16="","",元請入力データ!E16) -> 加賀中学校外壁改修その他工事現場事務所
B6: =IF(元請入力データ!E36="","",元請入力データ!E36) -> 遠藤 秀則 | P6: 殿
AF7: 年 月 日
AF8: =IF(下請入力データ!E3="","",下請入力データ!E3) -> 株式会社雅
AF9: =IF(下請入力データ!E5="","",下請入力データ!E5) -> 宮本紘光
C10: 外国人建設就労者の建設現場への入場について下記のとおり届出ます。
C11: 記
C12: １ 建設工事に関する事項
B13: 建設工事の名称 | M13: =IF(元請入力データ!E14="","",元請入力データ!E14) -> 加賀中学校外壁改修その他工事
B14: 施工場所 | M14: =IF(元請入力データ!E15="","",元請入力データ!E15) -> 足立区加賀二丁目25番22号
C16: ２ 建設現場への入場を届け出る外国人建設就労者に関する事項
L17: 外国人建設就労者１ | X17: 外国人建設就労者２ | AJ17: 外国人建設就労者３ | AX17: 【記入例】
B18: 氏名 | AX18: 周 白山
B19: 生年月日 | L19: 年 月 日 | X19: 年 月 日 | AJ19: 年 月 日 | AX19: 年 月 日
B20: 性別 | AX20: 男
B21: 国籍 | AX21: 中国
B22: 従事させる業務 | AX22: 基礎型枠工事（型枠工事作業）
B23: 現場入場の期間 | L23: 年 月 日 | X23: 年 月 日 | AJ23: 年 月 日 | AX23: 年 月 日
L24: ～ | N24: 年 月 日 | X24: ～ | Z24: 年 月 日 | AJ24: ～ | AL24: 年 月 日 | AX24: ～ | AZ24: 年 月 日
B25: 在留期間満了日 | L25: 年 月 日 | X25: 年 月 日 | AJ25: 年 月 日 | AX25: 年 月 日
C27: ３ 受入建設企業・適正監理計画に関する事項 | AX27: 【記入例】
B28: 適正監理計画認定番号 | AX28: B009999
B29: 受入建設企業の所在地 | AX29: 東京都千代川区神田3-1
B30: 元請企業との関係 （直近上位の企業名その他） | P30: （一次） | AF30: →（二次） | AX30: （一次） | BC30: 大川建設(株) | BN30: →（二次） | BS30: (株)山中工務店
P31: →（三次） | AF31: →（四次） | AX31: →（三次） | BC31: 石庭工業(株) | BN31: →（四次）
B32: 責任者 | P32: 役職 | AD32: 氏名 | AX32: 役職 | BB32: 取締役社長 | BL32: 氏名 | BP32: 山田三郎
B33: 管理指導員 | P33: 役職 | AD33: 氏名 | AX33: 役職 | BB33: 技術課長 | BL33: 氏名 | BP33: 城田正明
B34: 就労場所 | AX34: 関東地方
B35: 従事させる業務の内容 | AX35: 型枠工事作業
B36: 従事させる期間（計画期間） | P36: 年 月 日 | AE36: ～ | AG36: 年 月 日 | AX36: 年 月 日 | BM36: ～ | BO36: 年 月 日
B38: ○添付書類 提出にあたっては下記に該当するものの写し各1部を添付すること １ 適正監理計画認定証 ２ パスポート（国籍、氏名等と在留許可のある部分） ３ 在留カード又は外国人登録証明書 ４ 受入建設企業と外国人建設就労者との間の雇用契約書及び雇用条件書（労働条件通知書）

Sheet 名簿
A1: 全建統一様式第5号
AF2: 作業員名簿 | CH2: 元請 確認欄
A3: 事業所の名称 | H3: =IF(元請入力データ!E16="","",元請入力データ!E16) -> 加賀中学校外壁改修その他工事現場事務所 | AF3: （ | AH3: 年 月 日 | AV3: 作成） | CH3: 提出日 | CM3: 年 月 日
AD4: 本書面に記載した内容は、作業員名簿として、安全衛生管理や労働災害発生時の緊急連絡・対応のために元請負業者に提示することについて、記載者本人は同意しています。
A5: 所 長 名 | H5: =IF(元請入力データ!E36="","",元請入力データ!E36) -> 遠藤 秀則 | Y5: 殿 | BE5: 一 次 会社名 | BJ5: =IF(下請入力データ!E3="","",下請入力データ!E3) -> 株式会社雅 | CE5: （ | CI5: 次）
CE6: 会社名
A8: 番号 | C8: ふりがな | K8: 職種 | P8: ※ | T8: 雇入年月日 | AB8: 生年月日 | AK8: 現住所 | BA8: （TEL） | BI8: 最近の健康診断日 | BQ8: 血液型 | BS8: 特殊健康診断日 | CB8: 教育・資格・免許 | CT8: 入場年月日
C9: 氏 名 | T9: 経験年数 | AB9: 年 齢 | AK9: 家族連絡先 | BA9: （TEL） | BI9: 血圧 | BS9: 種類 | CB9: 雇入・職長 特別教育 | CH9: 技能講習 | CN9: 免許 | CT9: 受入教育 実施年月日
A10: 1 | T10: 年 月 日 | AB10: 年 月 日 | BI10: 年 月 日 | BS10: 年 月 日 | CT10: 年 月 日
T11: =IF(T10=" 年 月 日","",DATEDIF(T10,TODAY(),"Y")) | Y11: 年 | AB11: =IF(AB10=" 年 月 日","",DATEDIF(AB10,TODAY(),"Y")) | AG11: 歳 | BL11: ～ | CT11: 年 月 日
A12: 2 | T12: 年 月 日 | AB12: 年 月 日 | BI12: 年 月 日 | BS12: 年 月 日 | CT12: 年 月 日
T13: =IF(T12=" 年 月 日","",DATEDIF(T12,TODAY(),"Y")) | Y13: 年 | AB13: =IF(AB12=" 年 月 日","",DATEDIF(AB12,TODAY(),"Y")) | AG13: 歳 | BL13: ～ | CT13: 年 月 日
A14: 3 | T14: 年 月 日 | AB14: 年 月 日 | BI14: 年 月 日 | BS14: 年 月 日 | CT14: 年 月 日
T15: =IF(T14=" 年 月 日","",DATEDIF(T14,TODAY(),"Y")) | Y15: 年 | AB15: =IF(AB14=" 年 月 日","",DATEDIF(AB14,TODAY(),"Y")) | AG15: 歳 | BL15: ～ | CT15: 年 月 日
A16: 4 | T16: 年 月 日 | AB16: 年 月 日 | BI16: 年 月 日 | BS16: 年 月 日 | CT16: 年 月 日
T17: =IF(T16=" 年 月 日","",DATEDIF(T16,TODAY(),"Y")) | Y17: 年 | AB17: =IF(AB16=" 年 月 日","",DATEDIF(AB16,TODAY(),"Y")) | AG17: 歳 | BL17: ～ | CT17: 年 月 日
A18: 5 | T18: 年 月 日 | AB18: 年 月 日 | BI18: 年 月 日 | BS18: 年 月 日 | CT18: 年 月 日
T19: =IF(T18=" 年 月 日","",DATEDIF(T18,TODAY(),"Y")) | Y19: 年 | AB19: =IF(AB18=" 年 月 日","",DATEDIF(AB18,TODAY(),"Y")) | AG19: 歳 | BL19: ～ | CT19: 年 月 日
A20: 6 | T20: 年 月 日 | AB20: 年 月 日 | BI20: 年 月 日 | BS20: 年 月 日 | CT20: 年 月 日
T21: =IF(T20=" 年 月 日","",DATEDIF(T20,TODAY(),"Y")) | Y21: 年 | AB21: =IF(AB20=" 年 月 日","",DATEDIF(AB20,TODAY(),"Y")) | AG21: 歳 | BL21: ～ | CT21: 年 月 日
A22: 7 | T22: 年 月 日 | AB22: 年 月 日 | BI22: 年 月 日 | BS22: 年 月 日 | CT22: 年 月 日
T23: =IF(T22=" 年 月 日","",DATEDIF(T22,TODAY(),"Y")) | Y23: 年 | AB23: =IF(AB22=" 年 月 日","",DATEDIF(AB22,TODAY(),"Y")) | AG23: 歳 | BL23: ～ | CT23: 年 月 日
A24: 8 | T24: 年 月 日 | AB24: 年 月 日 | BI24: 年 月 日 | BS24: 年 月 日 | CT24: 年 月 日
T25: =IF(T24=" 年 月 日","",DATEDIF(T24,TODAY(),"Y")) | Y25: 年 | AB25: =IF(AB24=" 年 月 日","",DATEDIF(AB24,TODAY(),"Y")) | AG25: 歳 | BL25: ～ | CT25: 年 月 日
A26: 9 | T26: 年 月 日 | AB26: 年 月 日 | BI26: 年 月 日 | BS26: 年 月 日 | CT26: 年 月 日
T27: =IF(T26=" 年 月 日","",DATEDIF(T26,TODAY(),"Y")) | Y27: 年 | AB27: =IF(AB26=" 年 月 日","",DATEDIF(AB26,TODAY(),"Y")) | AG27: 歳 | BL27: ～ | CT27: 年 月 日
A28: 10 | T28: 年 月 日 | AB28: 年 月 日 | BI28: 年 月 日 | BS28: 年 月 日 | CT28: 年 月 日
T29: =IF(T28=" 年 月 日","",DATEDIF(T28,TODAY(),"Y")) | Y29: 年 | AB29: =IF(AB28=" 年 月 日","",DATEDIF(AB28,TODAY(),"Y")) | AG29: 歳 | BL29: ～ | CT29: 年 月 日
A30: 11 | T30: 年 月 日 | AB30: 年 月 日 | BI30: 年 月 日 | BS30: 年 月 日 | CT30: 年 月 日
T31: =IF(T30=" 年 月 日","",DATEDIF(T30,TODAY(),"Y")) | Y31: 年 | AB31: =IF(AB30=" 年 月 日","",DATEDIF(AB30,TODAY(),"Y")) | AG31: 歳 | BL31: ～ | CT31: 年 月 日
A33: (注)1. ※印欄には次の文字を入れる。 現・・・現場代理人 主・・・作業主任者（(注)2.） 女・・・女性作業員 未・・・18歳未満の作業員 基・・・基幹技能者 技・・・主任技術者 職・・・職長 安・・・安全衛生責任者 能・・・能力向上教育 再・・・危険有害業務・再発防止教育 習・・・外国人技能実習生 就・・・外国人建設就労者 (注)2. 作業主任者は作業を直接指揮する義務を負うので、同時に施工されている他の現場や、同一現場においても他の作業個所との作業主任者を兼務することは、法的に認められていないので、複数の選任としなければならない。 | BD33: (注)3. 経験年数は現在担当している仕事の経験年数を記入する。 (注)4. 各社別に作成するのが原則であるが、リース機械等の運転者は一緒でもよい。 (注)5. 資格・免許等の写しを添付すること。

Sheet 作業員名簿
P1: 作業員名簿
P2: （R６年10月14日作成) | AG2: 元請 確認欄
A3: 事業所の名称 | F3: 一新建設株式会社
A4: 所長名 | N4: 本書面に記載した内容は、作業員名簿として安全衛生管理や 労働災害発生時の緊急連絡対応のために元請業者に提示する ことについて、記載者本人は同意しています。
Y6: 一次会社名 | Z6: 株式会社雅 | AG6: （ 次)会社名
Y7: 代表者名 | Z7: 宮本紘光 | AG7: 代表者名
Z8: [建退共加入の有無 有・無] | AJ8: [建退共加入の有無 有・無]
A10: 番号 | B10: ふりがな | F10: 職種 | I10: ＊１ | J10: 雇入年月日 | M10: 生年月日 | P10: 現住所 | V10: （ＴＥＬ) | Y10: 最 近 の 健康診断日 | Z10: 血液型 | AA10: 特 殊 健康診断日 | AB10: 健康保険７ | AD10: 教 育・資 格・免 許 | AK10: 入場年月日 | AL10: 建退共手帳 所有の 有無
AB12: 年金保険８
B13: 氏名 | J13: 経験年数 | M13: 年齢 | P13: 家族連絡先 | V13: （ＴＥＬ) | Y13: 血 圧 | AA13: 種 類 | AD13: 雇入･職長 特別教育 | AE13: 技能講習 | AJ13: 免 許 | AK13: 受入教育 実施年月日
AB14: 雇用保険９
A16: 1 | B16: みやもとひろき | F16: 左官 | J16: １年 10月1日 | M16: H５年11月23日 | P16: 埼玉県所沢市狭山ヶ丘1‐2994-1 グリーンハイム202 | V16: ( 080-5199-6997) | Y16: R6年9月1日 | Z16: A | AA16: 年 月 日 | AB16: 6881 | AK16: 年 月 日 | AL16: 有
B18: 宮本紘光
J19: １１年 | M19: 30歳 | P19: 埼玉県所沢市東狭山ヶ丘2-2898-4 | V19: (090-4825-6907) | Y19: 95～110 | AK19: 年 月 日 | AL19: 無
AB20: 適用除外
A22: 2 | B22: おまたたくや | F22: 左官 | J22: R2年7月1日 | M22: H５年12月6日 | P22: 埼玉県所沢市山口1385-3 | V22: (080-9690-7285) | Y22: R6年9月1日 | Z22: B | AA22: 年 月 日 | AK22: 年 月 日 | AL22: 有
B24: 小俣拓也 | AB24: 7076
J25: 11年 | M25: 30歳 | P25: 同上 | V25: (090-9390-1602) | Y25: nenn | AK25: 年 月 日 | AL25: 無
AB26: 4737
A28: 3 | B28: さわだゆうき | F28: 左官 | J28: R4年1月1日 | M28: H13年3月18日 | P28: 埼玉県所沢市狭山ヶ丘1‐2008-2ユアコート狭山ヶ丘コンクリフィア304号室 | V28: (070-1067-4729) | Y28: R6年9月1日 | Z28: A | AA28: 年 月 日 | AK28: 年 月 日 | AL28: 有
B30: 澤田祐樹 | AB30: 8326
J31: 3年 | M31: 22歳 | P31: 同上 | V31: (048-762-9425) | Y31: 90～110 | AK31: 年 月 日 | AL31: 無
AB32: 1312
A34: 4 | B34: ひがきりきと | F34: 左官 | J34: R4年6月1日 | M34: H16年9月29日 | P34: 埼玉県所沢市狭山ヶ丘1-2994‐5 スウィートヒルズ208 | V34: (090-3685-5560) | Y34: R6年9月1日 | Z34: A | AA34: 年 月 日 | AB34: 0010 | AK34: 年 月 日 | AL34: 有
B36: 檜垣力渡
J37: 2年 | M37: 19歳 | P37: 埼玉県所沢市狭山ヶ丘1-2994‐１グリーンハイム205 | V37: (080-9449-0171) | Y37: 95～110 | AK37: 年 月 日 | AL37: 無
AB38: 適用除外
A40: 5 | AK40: 年 月 日 | AL40: 有
AK43: 年 月 日 | AL43: 無
A46: 6 | AK46: 年 月 日 | AL46: 有
AK49: 年 月 日 | AL49: 無
A52: 7 | AK52: 年 月 日 | AL52: 有
AK55: 年 月 日 | AL55: 無
A58: 8 | AK58: 年 月 日 | AL58: 有
AK61: 年 月 日 | AL61: 無
A65: （注)１.＊印欄には次の記号を入れる。 | Z65: ２．作業員名簿に記載される作業員は、当該工事に従事する見込の者を必要最小限報告し、
B67: …現場代理人 | F67: …作業主任者（正副2名を選任すること) | N67: …女性作業員 | R67: …18歳未満の作業員 | Z67: 追加の都度この様式で提出する。
B69: …主任技術者 | F69: …職 長 | I69: …安全衛生責任者 | N69: …能力向上教育（※) | T69: …危険有害業務・再発防止教育 | Z69: ３．経験年数は現在担当している仕事の経験年数を記入する。
Z70: ４．各社別に作成するのが原則だが、リース機械等の運転者は一緒でもよい。
A71: （※)能力向上教育は、平成3年1月21日付旧労働省労働基準局基発第39号「安全衛生教育の推進について」により定められた職長等の「能力向上教育に準じた教育」を指す。 | Z71: ５．資格・免許等の写しを添付することになるが、その場で本証とチェック出来れば不要。
...

Sheet 社会保険
B1: 全建統一様式第5号－別紙 | AD1: 元 請 確認欄
AD3: 提出日 | AI3: 年 月 日
M4: 社会保険加入状況
M5: （ | Q5: 年 月 日 | AE5: 作成）
B7: 事業所 の名称 | G7: =IF(元請入力データ!E16="","",元請入力データ!E16) -> 加賀中学校外壁改修その他工事現場事務所
G8: =IF(元請入力データ!E36="","",元請入力データ!E36) -> 遠藤 秀則 | Q8: 殿 | S8: 一次 会社名 | W8: =IF(下請入力データ!E3="","",下請入力データ!E3) -> 株式会社雅 | AG8: （ | AJ8: 次）
B9: 所長名 | AG9: 会社名
B11: 番号 | D11: ふ り が な | O11: 社 会 保 険
D12: 氏 名
O13: 健康保険 | Z13: 年金保険 | AK13: 雇用保険
B14: 1
B16: 2
B18: 3
B20: 4
B22: 5
B24: 6
B26: 7
B28: 8
B30: 9
B32: 10
B34: （注）個人情報保護の観点から、被保険者番号等は本人の同意を得たうえで記載する。 （記入要領） １．健康保険欄には、上段に健康保険の名称（健康保険組合、協会けんぽ、建設国保、国民健康保険）を、下段に健康保険被保険者証の番号の下4桁（番号が4桁以下の場合は、当該番号）を記載する。なお、上記の保険に加入しておらず、後期高齢者である等により、国民健康保険の適用除外である場合には、上段に「適用除外」と記載する。 ２．年金保険欄には、上段に年金保険の名称（厚生年金、国民年金等）を、各年金の受給者である場合は、上段に「受給者」と記載する。 ３．雇用保険欄には、下段に被保険者番号の下4桁（日雇労働被保険者の場合は、上段に「日雇保険」と）を、事業主である等により雇用保険の適用除外である場合は、上段に「適用除外」と記載する。

Sheet 年度計画
B1: 参考様式第3号
AO2: 元 請 確認欄
B4: 事業所の名称 | H4: =IF(元請入力データ!E16="","",元請入力データ!E16) -> 加賀中学校外壁改修その他工事現場事務所 | AM4: 会社名 | AQ4: =IF(下請入力データ!E3="","",下請入力データ!E3) -> 株式会社雅
B6: 所 長 名 | H6: =IF(元請入力データ!E36="","",元請入力データ!E36) -> 遠藤 秀則 | T6: 殿 | AM6: 代表者名 | AQ6: =IF(下請入力データ!E5="","",下請入力データ!E5) -> 宮本紘光
AM8: R6年 １０月 14日 | BC8: 作成
I11: 令和４ | P11: 年度（ | T11: 4 | W11: 年 | Y11: 4 | AA11: 月～ | AD11: 5 | AG11: 年 | AI11: 3 | AK11: 月）安全衛生計画書
B14: 安全衛生方針 | J14: 労働安全衛生関係法令及び当社の安全衛生管理規定を遵守する
B16: 安全衛生目標 | J16: 安全衛生の達成率を８０％以上とする。 全ての安全情報を作業員一人一人に確実に伝達する。
B18: 安全衛生上の課題及び特定した危険性又は有害性
B19: 安全衛生パトロールによる指摘事項の改善が展開されていなかった 教育が計画通りに行われていなかった
B21: 安 全 衛 生 計 画
B22: 重点施策 | H22: 実施事項 | N22: 管理目標 （管理点） | T22: 実務担当 | Z22: 実施スケジュールと評価スケジュール | AX22: 実施上の留意点
Z23: 4月～6月 | AF23: 7月～9月 | AL23: 10月～11月 | AR23: 1月～3月
B24: 安全衛生教育の計画的実施 | H24: ①送出し教育の実施 ②CFT教育の実施 | N24: 現場配置の 全従業員・回数 職長・安責者・回数 | Z24: ①→５月 | AF24: ②→７月 | AL24: ①→１１月 | AX24: 作業手順の遵守を指導 詳細は、実施計画による
Z25: （教育実施後に評価）
B26: リスクアセスメントの推進 | H26: 作業手順書によるリスクアセスメント及び対策の実施 | N26: 工事開始前８０％ | AX26: 丁寧な見積り評価と合理的な対策
B28: 安全パトロールの実施 | H28: ①安全パトロールの強化による不安全状態、不安全行動の排除 ②指摘事項及び改善内容の展開 | N28: 協議会時 | AX28: リスクアセスメントの実施状況確認 安全ルールに遵守指導
Z29: （８月・１２月・２月に評価）
B32: 作業所共通の重点施策・実施事項
B33: 重点対策 | J33: 実施事項 | AD33: 重点対策 | AL33: 実施事項
B34: 墜落災害防止措置の徹底 | J34: ・脚立足場の安全使用 | AD34: 車両系建設機械災害防止措置の徹底 | AL34: 用途外使用の禁止
J35: ・開口部の養生 | AL35: 旋回・走行範囲立入禁止、誘導による走行
J36: ・安全帯の仕様 | AL36: グーパー合図の徹底
B37: 作業中の安全衛生管理活動の推進 | J37: ・現地KYの「私たちはこうする」を守る | AD37: 移動式クレーン災害防止措置の徹底 | AL37: アウトリガーの最大張出し
J38: ・作業手順書の低減対策の遵守
J39: ・作業開始前、作業中に安全確認を行う
B41: 安 全 衛 生 行 事
B42: 4月 | E42: 社内協議会 | AD42: 10月 | AG42: 安全労働衛生週間
B43: 5月 | AD43: 11月 | AG43: 定期健康診断
B44: 6月 | E44: 全国安全週間準備期間 | AD44: 12月 | AG44: 年末年始労働災害防止期間
B45: 7月 | E45: 全国安全週間準備期間 | AD45: 1月
B46: 8月 | E46: 熱中症予防月間 | AD46: 2月
B47: 9月 | E47: 全国労働衛生週間準備期間 | AD47: 3月 | AG47: 年度末労働災害防止強調月間
B49: 安 全 衛 生 管 理 体 制
B50: 管理者区分 | V50: 役 職 名 | AN50: 氏 名
B51: 安全衛生担当役員
B52: 雇用管理責任者 | V52: 代表取締役 | AN52: 伊藤 太樹
B53: 総括安全衛生管理者
B54: 安全管理者
B55: 衛生管理者
...

Sheet 安全計画
B1: 全建統一様式6号
AP2: 元請 確認欄
B4: 事業所の名称 | H4: =IF(元請入力データ!E16="","",元請入力データ!E16) -> 加賀中学校外壁改修その他工事現場事務所 | AN4: 会 社 名 | AT4: =IF(下請入力データ!E3="","",下請入力データ!E3) -> 株式会社雅
B6: 所長名 | H6: =IF(元請入力データ!E36="","",元請入力データ!E36) -> 遠藤 秀則 | S6: 殿 | AN6: 現場代理人 | AT6: =IF(下請入力データ!E37="","",下請入力データ!E37) -> 小俣拓也
AN7: （現場責任者）
AP8: R６ 年 １０月 １４ 日 | BC8: 作成
R10: 工事安全衛生計画書
B13: 工事安全衛生方針
B16: 工事安全衛生目標
B19: 工 種 | J19: 工 種 別 工 事 期 間 | AT19: 日常の安全衛生活動
B26: 資機材・保護具・資格の区分/その種類
B27: 主な使用機械設備
B28: 主な使用機器・工具
B29: 主な使用資材
B30: 使用保護具
B31: 有資格者・配置予定者
B32: １．危険性又は有害性の特定 | W32: ２．リスクの見積り | AI32: ３．リスク低減措置内容の検討
B33: 作業区分 | J33: 予想される災害（危険性又は有害性） | W33: 可能性 （度合） | Z33: 重大性 （重篤度） | AC33: 見積り | AF33: リスク レベル | AI33: リスク低減措置
B66: 職 名 | N66: 氏 名 | AA66: 再下請会社の関係者の職名・氏名・会社名等
B67: 店社 | D67: 安全衛生担当責任者 | AA67: 職名 | AI67: 氏名 | AS67: 再 下 請 会 社 名
D68: 工事担当責任者 | AU68: 次
AU69: 次
B70: 事業所 | D70: 現場代理人 | AU70: 次
D71: 安全衛生責任者 | AU71: 次
D72: 職長 | AU72: 次
AU73: 次
Q75: 元請工事業者提出書類一覧 | AQ75: 注）□は、レ点でチェック。
D76: 再下請負通知書 | R76: 下請業者編成表 | AF76: 作業員名簿 | AT76: 持込機械等（ | BB76: ）使用届
D77: 持込機械等（移動式クレーン）使用届 | R77: 持込機械等（車両系建設機械）使用届 | AF77: 持込機械等（電動工具）使用届 | AT77: 持込機械等（電気溶接機）使用届
D78: 工事用車両届 | R78: 危険物・有害物持込使用届 | AF78: 火気使用届
D79: 送出し教育実施報告書 | R79: 新規入場時教育実施報告書
D80: （ | K80: ） | L80: 作業計画書 | R80: （ | Y80: ） | Z80: 作業計画書 | AF80: （ | AM80: ） | AN80: 作業手順書 | AT80: （ | BA80: ） | BB80: 作業手順書
D81: 安全衛生計画書

Sheet 新規報告
B1: 全建統一様式第7号 | AE1: 元 請 確認欄
AE3: 年 月 日
M5: 新規入場時等教育実施報告書
C6: 事業所の名称 | I6: =IF(元請入力データ!E16="","",元請入力データ!E16) -> 加賀中学校外壁改修その他工事現場事務所
C7: 所長名 | I7: =IF(元請入力データ!E36="","",元請入力データ!E36) -> 遠藤 秀則 | W7: 殿
Z8: 会社名 | AG8: =IF(下請入力データ!E3="","",下請入力データ!E3) -> 株式会社雅
Z9: 現場代理人
Z10: （現場責任者） | AG10: =IF(下請入力データ!E37="","",下請入力データ!E37) -> 小俣拓也
C12: 項目 | M12: 摘 要
C13: 教育の種類 | M13: 新規入場時 ・ 雇 入 時 ・ 送り出し時
C14: 実施日時 | M14: 年 月 日 時 ～ 時 （ 時間 ）
C15: 実施場所
C16: 教育方法
C17: 教育内容
C27: 講師
C29: 受講者氏名 （受講者に氏名を自筆させること）
C36: 資料
C38: （注） 新規入場者調査票が作成される場合は本様式の提出は不要

Sheet 新規調査
B1: 参考様式第4号
AJ2: 新規入場日 | AR2: 年 月 日
D3: 新規入場者調査票 | AL3: 元 請 確認欄
C4: （ | D4: =IF(元請入力データ!E16="","",元請入力データ!E16) -> 加賀中学校外壁改修その他工事現場事務所 | AC4: 作業所 | AH4: ）
C5: 下記調査票の個人情報については、安全衛生管理及び緊急時の連絡・対応のために使用いたします。また、当社において厳重に管理し、法令に定める場合を除き、第三者には提供いたしません。不要となった時は、責任をもって処分いたします。
B6: ふりがな | U6: 生年月日 | AR6: （ | AV6: ）歳 | AY6: 血液型
B7: 氏名
B8: 現住所
AJ9: TEL
B10: 緊 急 連 絡 先
B11: 氏 名 | R11: 続柄 | W11: 電話番号 | AI11: 現 住 所
B13: <あなたが働いている会社との関係>
B14: 事業者名 | I14: （一次） | O14: =IF(下請入力データ!E3="","",下請入力データ!E3) -> 株式会社雅 | AG14: 雇用年月日： | AN14: 年 月 日
B15: 所属会社
B16: 雇用契約書 | I16: １． 取り交わし済み ２． 未 だ | AG16: 職種：
B17: （アンケートにお答えください）
B18: ・あなたは一人親方・中小事業主ですか | AF18: １． はい ２． いいえ
B19: １．に○を付けた方は、労災保険に特別加入していますか。 | AF19: １． している ２． 未加入
B20: ・あなたは建設現場で働きはじめてどれくらいになりますか。 | AF20: １．1年以内 ２．1～3年 ３．3年以上
B21: ・あなたは健康診断を受けましたか。 | AF21: １．受けた（ | AL21: 年 月 | AT21: ） ２．受けていない
B22: ・あなたの最近の健康状態はどうですか。 | AF22: １．よい ２．まあまあである ３．あまりよくない
B23: ・この現場に来る前に事業主から送り出し教育を受けてきましたか。 | AF23: １．はい ２． いいえ
B24: ＜資格について＞
B25: 技能講習 （作業主任者・作業者） | O25: ガス溶接 | W25: 玉掛け | AI25: コンクリート破砕器 | AU25: 地山の掘削 | BC25: 石綿
O26: 有機溶剤 | W26: 型枠支保工の組立て等 | AI26: 足場の組立て等 | AU26: ボイラー取扱
O27: コンクリート造の工作物の解体等 | AI27: 酸素欠乏危険 | AU27: その他（ ）
B28: 技能講習 （運転士） | O28: 1t以上5t未満の移動式クレーン | AL28: 3t以上の車両系建設機械
O29: 3t以上の自走する基礎工事用機械 | AL29: 3t以上の解体用機械
O30: 1t以上の不整地運搬車 | AL30: 10m以上の高所作業車
O31: 1t以上のフォークリフト | AL31: 1t以上のショベルローダー
O32: その他（ ）
B34: 特別教育 （運転者・作業者） | O34: 酸素欠乏危険作業 | AC34: 3t未満の車両系建設機械 | AT34: 3t未満の自走しない基礎工事用機械
O35: ローラー | AC35: ｺﾝｸﾘｰﾄ打設用車両系建設機械 | AT35: 3t未満の解体用機械
O36: 不整地運搬車（1t未満） | AC36: 10m未満の高所作業車 | AT36: ボーリングマシン
O37: ﾌｫｰｸﾘﾌﾄ（1t未満） | AC37: ｼｮﾍﾞﾙﾛｰﾀﾞｰ（1t未満） | AT37: 巻き上げ機
O38: 建設用リフト | AC38: 1t未満の玉掛け | AT38: ゴンドラ
O39: アーク溶接等 | AC39: 研削といしの取替え等 | AT39: 電気取扱
O40: その他（ ）
AF49: 回答者直筆サイン

Sheet 機械使用
C1: 全建統一様式第9号 | AJ1: 年 月 日 | BF1: 持込時の点検表 | CQ1: 機械名 (1) クレーン (2) 移動式クレーン (3) デリック (4) エレベーター (5) 建設用リフト (6) 高所作業車 (7) ゴンドラ (8) ブル・ドーザー (9) モーター・グレーダー (10) トラクターショベル (11) ずり積機 (12) スクレーバー (13) スクレーブ・ドーザー (14) パワー・ショベル (15) ドラグ・ショベル （油圧ショベル） (16) ドラグライン (17) クラムシェル (18) バケット掘削機 (19) トレンチャー (20) コンクリート圧砕機 (21) くい打機 (22) くい抜機 (23) アース・ドリル (24) リバース・サーキュレー ション・ドリル (25) せん孔機 (26) アース・オーガー (27) ペーパー・ドレーン・ マシン (28) 地下連続壁施工機械 (29) ローラー (30) クローラドリル (31) ドリルジャンボ (32) ロードヘッダー (33) アスファルトフィ ニッシャー (34) スラビライザー (35) ロードプレーナ (36) ロードカッター (37) コンクリート吹付機 (38) ボーリングマシン (39) ブレーカ (40) 鉄骨切断機 (41) 解体用つかみ機 (42) 重ダンプトラック (43) ダンプトラック (44) トラックミキサー (45) 散水車 (46) 不整地運搬車 (47) コンクリートポンプ車 (48) その他
BF3: 所有会社名 | BX3: 代表者名
P4: 移動式クレーン | AC4: 等 | AG4: 使用届
P6: 車両系建設機械 | BF6: 移動式クレーン等 | BX6: 車両系建設機械等
BF7: 点検事項 | BT7: 点検結果 | BX7: 点検事項 | CL7: 点検結果
BT8: (a) | BV8: (b) | CL8: (a) | CN8: (b)
C9: 事業所の名称 | I9: =IF(元請入力データ!E16="","",元請入力データ!E16) -> 加賀中学校外壁改修その他工事現場事務所 | AA9: 一次会社名 | AG9: =IF(下請入力データ!E3="","",下請入力データ!E3) -> 株式会社雅 | BF9: Ａクレーン部（上部旋回体） | BI9: 安全装置 | BJ9: 巻過防止装置 | BX9: Ｄ安全装置 | CA9: 各種ロック | CB9: 旋回
BJ10: 過負荷防止装置 | CB10: バケット
C11: 所長名 | I11: =IF(元請入力データ!E36="","",元請入力データ!E36) -> 遠藤 秀則 | V11: 殿 | AA11: 持込会社名 | BJ11: フックのはずれ止め | CB11: ブーム・アーム
AA12: （ | AE12: 次） | BJ12: 起伏制御装置
AA13: 代表者名 | AG13: =IF(下請入力データ!E5="","",下請入力データ!E5) -> 宮本紘光 | BJ13: 旋回警報装置
BI14: 制御装置・作業装置 | BJ14: 主巻・補巻
AA15: 電話 | AG15: =IF(下請入力データ!E9="","",下請入力データ!E9) -> ０８０ | AJ15: － | AL15: =IF(下請入力データ!G9="","",下請入力データ!G9) -> ５１９９ | AP15: － | AR15: =IF(下請入力データ!I9="","",下請入力データ!I9) -> ６９９７ | BJ15: 起伏・旋回 | CA15: 警報装置
BJ16: クラッチ | CA16: アウトリガー
BJ17: ブレーキ・ロック | CA17: ヘッドガード
E18: このたび、下記機械等を裏面の点検表により、点検整備のうえ持込・使用しますので、お届けします。なお、使用に際しては関係法令に定められた事項を遵守します。 | BJ18: ジブ | CA18: 照明
BJ19: 清車 | BX19: Ｅ作業装置 | CA19: 操作装置
BJ20: フック・バケット | CA20: バケット・ブレード
E21: 使用会社名 | AC21: 代表者名 | BJ21: ワイヤロープ・チェーン | CA21: ブーム・アーム
E22: =IF(下請入力データ!E3="","",下請入力データ!E3) -> 株式会社雅 | V22: （ | X22: 一 | AA22: 次） | AC22: =IF(下請入力データ!E5="","",下請入力データ!E5) -> 宮本紘光 | BJ22: 玉掛用具 | CA22: ジブ
BI23: その他 | BJ23: 操作装置 | CA23: リーダ
BJ24: 性能表示 | CA24: ﾊﾝﾏ･ｵｰｶﾞ・ﾊﾞｲﾌﾞﾛ
M25: 名称 | U25: メーカー | AC25: 規格・性能 | AM25: 製造年 | AR25: 管理番号 （整理番号） | BJ25: 照明 | CA25: 油圧駆動装置
BF26: Ｂ車両部（下部走行体） | BI26: 走行部 | BJ26: ブレーキ | CA26: ワイヤロープ・チェーン
E27: 機械 | BJ27: クラッチ | CA27: 吊り具等
BJ28: ハンドル | CA28: 滑車
E29: 持込年月日 | M29: 年 月 日 | Y29: 使用場所 | AM29: 自社・リースの区分 | BJ29: タイヤ | BX29: Ｆ走行部 | CA29: ブレーキ
BJ30: クローラ | CA30: 駐車ブレーキ
E31: 搬出予定年月日 | M31: 年 月 日 | AM31: 自社 ・ リース | BI31: 安全装置等 | BJ31: 警報装置 | CA31: ブレーキ・ロック
BJ32: 各種ミラー | CA32: クラッチ
E33: 運転者 （取扱者） | M33: 氏名 | Y33: 資格の種類 | BJ33: 方向指示器 | CA33: 操縦装置
M34: （正） | BJ34: 前後照灯 | CA34: タイヤ・鉄輪
BJ35: 左折プロテクター | CA35: クローラ
M36: （副） | BJ36: アウトリガー | BX36: Ｇ電気装置 | CA36: 配電盤
BJ37: 昇降装置 | CA37: 配線
E38: 有効期限 自主検査 | H38: 定期 | J38: 年次 | M38: 年 月 日 | V38: 移動式クレーン等の性能検査有効期限 | AA38: 年 月 日 | AJ38: 自動車 検査証 有効期限 | AN38: 年 月 日 | BJ38: ベッセル | CA38: 絶縁
BJ39: 後方監視装置 | CA39: アース
J40: 月次 | M40: 年 月 日 | BF40: Ｃゴンドラ | BJ40: 突りょう
BJ41: 作業床 | BX41: Ｈその他
H42: 特定 | M42: 年 月 日 | BJ42: 昇降装置
...

Sheet 持込工具
C1: 参考様式第6号 | AH1: 年 月 日 | BG1: 持込時の点検表
BV3: 点検 | BX3: 年 月 日
I5: 持込機械等 | S5: 電動工具 | AD5: 等 | AG5: 使用届 | BG5: 電動工具・電気溶接機等
CD6: 機 械 名 (1) 電動カンナ (2) 電動ドリル (3) 電動丸のこ (4) グラインダー等 (5) アーク溶接機 (6) ウインチ (7) 発電機 (8) トランス (9) コンプレッサー (10) 送風機 (11) ポンプ類 (12) ミキサー類 (13) コンベヤー (14) 吹付機 (15) ボーリングマシン (16) 振動コンバクター (17) バイブレーター (18) 鉄筋加工機 (19) 電動チェーンブロック (20) その他
BG7: 点検事項 | BM7: 番号 | BS7: 1 | BT7: 2 | BU7: 3 | BV7: 4 | BW7: 5 | BX7: 6 | BY7: 7 | BZ7: 8 | CA7: 9 | CB7: 10
S8: 電気溶接機
BG10: アース線
C12: 事業所の名称 | I12: =IF(元請入力データ!E16="","",元請入力データ!E16) -> 加賀中学校外壁改修その他工事現場事務所 | Z12: 一次会社名 | AF12: =IF(下請入力データ!E3="","",下請入力データ!E3) -> 株式会社雅
BG13: 接地クランプ
C15: 所長名 | I15: =IF(元請入力データ!E36="","",元請入力データ!E36) -> 遠藤 秀則 | V15: 殿 | Z15: 持込会社名
BG16: キャップタイヤ
Z17: （ | AD17: 次）
AF18: =IF(下請入力データ!E5="","",下請入力データ!E5) -> 宮本紘光
Z19: 代表者名 | BG19: コネクタ
Z21: 電話 | AF21: =IF(下請入力データ!E9="","",下請入力データ!E9) -> ０８０ | AI21: － | AK21: =IF(下請入力データ!G9="","",下請入力データ!G9) -> ５１９９ | AO21: － | AQ21: =IF(下請入力データ!I9="","",下請入力データ!I9) -> ６９９７
BG22: 接地端子の締結
BG25: 充電部の絶縁
C26: このたび、下記機械等を裏面の点検表により、点検整備のうえ持込・使用しますので、お届けします。なお、使用に際しては関係法令に定められた事項を遵守します。
BG28: 自動電撃防止装置
BG31: 絶縁ホルダー
C32: 記
B34: 番号 | E34: 機械名 | O34: 規 格 性 能 | V34: 管理番号 受付番号 | AA34: 持込年月日 搬出予定年月日 | AI34: 点検者 | AO34: 取扱者 | BG34: 溶接保護面
B37: 1 | AA37: 年 月 日 | BG37: 操作スイッチ
AA39: 年 月 日
BG40: 絶縁抵抗測定値
B41: 2 | AA41: 年 月 日
AA43: 年 月 日 | BG43: 各種ブレーキの作動
B45: 3 | AA45: 年 月 日
BG46: 手すり・囲い
AA47: 年 月 日
B49: 4 | AA49: 年 月 日 | BG49: フックのはずれ止め
AA51: 年 月 日
BG52: ワイヤロープ・チェーン
B53: 5 | AA53: 年 月 日
AA55: 年 月 日 | BG55: 滑車
B57: 6 | AA57: 年 月 日
BG58: 回転部の囲い等
AA59: 年 月 日
B61: 7 | AA61: 年 月 日 | BG61: 危険表示
AA63: 年 月 日
...

Sheet 車両
A1: 参考様式第8号 | AC1: 元 請 確認欄
AG3: 年 月 日
N6: 工事
T7: 用車両届
N8: 通勤
A11: 事業所の名称 | H11: =IF(元請入力データ!E16="","",元請入力データ!E16) -> 加賀中学校外壁改修その他工事現場事務所 | AE11: =IF(下請入力データ!E3="","",下請入力データ!E3) -> 株式会社雅
Y12: 一次会社名
A13: 所長名 | H13: =IF(元請入力データ!E36="","",元請入力データ!E36) -> 遠藤 秀則 | U13: 殿 | Y13: 使用会社名
Y14: ( | Z14: 一 | AB14: 次）
Y15: 現場代理人 | AE15: =IF(下請入力データ!E37="","",下請入力データ!E37) -> 小俣拓也 | AR15: 印
Y16: (現場責任者)
F19: 下記の通り | N19: （工事・通勤） | U19: 用車両を運行しますので、お届けいたします。
A21: 使用期間 | J21: 年 月 日 | Z21: ～ | AD21: 年 月 日
A23: 所有者氏名 | Z23: 安全運転 管理者氏名
A25: 車両 | C25: 型式 | Z25: 車両番号 | AH25: 足立480 せ 42-53
C27: 車検期間 | J27: 年 月 日 | Z27: ～ | AD27: 年 月 日
A29: 運転者 | C29: 氏名 | J29: 池田 哲也 | Z29: 生年月日 | AH29: 26469
C31: 住所 | J31: 東京都足立区南花畑5-23-27
C33: 免許の種類 | J33: 中型 | Z33: 免許番号 | AH33: 44209047232
A35: 自賠責 | C35: 保険会社名 | Z35: 証券番号
C37: 保険期間 | J37: 年 月 日 | Z37: ～ | AD37: 年 月 日
A39: 任意保険 | C39: 保険会社名 | Z39: 証券番号
C41: 対人 | R41: 対物 | AF41: 搭乗者
C43: 保険期間 | J43: 年 月 日 | Z43: ～ | AD43: 年 月 日
A45: 運行経路 | J45: 自 | L45: 東京管工機材株式 | R45: ～経由 | V45: 第九中学校 | AA45: ～経由 | AE45: 第九中学校 | AJ45: ～至 | AM45: 東京管工機材株式
C48: (注) １．この届出書は車両1台ごとに提出すること。 ２．この届出書に「任意保険」の証書（写）を添付し提出すること。 ３．運転者が変わった場合はその都度届け出ること。

Sheet 有機
B1: 全建統一様式第11号 | AE1: 元 請 確認欄
AE3: 年 月 日
G6: 有機溶剤・特定化学物質等持込使用届
B10: 事業所の名称 | H10: =IF(元請入力データ!E16="","",元請入力データ!E16) -> 加賀中学校外壁改修その他工事現場事務所 | Y10: 一次会社名 | AE10: =IF(下請入力データ!E3="","",下請入力データ!E3) -> 株式会社雅
B12: 所長名 | H12: =IF(元請入力データ!E36="","",元請入力データ!E36) -> 遠藤 秀則 | V12: 殿 | Y12: 使用会社名
Y13: （ | AC13: 次）
Y14: 現場代理人 | AE14: =IF(下請入力データ!E37="","",下請入力データ!E37) -> 小俣拓也 | AR14: 殿
Y15: （現場責任者）
E16: このたび、下記の有機物質・特定化学物質等を持込・使用するのでお届けします。なお、使用に際しては、ＳＤＳ（安全データシート）内容を掲示し、作業員に対して周知を行うとともに関係法規を遵守します。
B19: 使用材料 | J19: 商品名 | S19: メーカー名 | Z19: 搬入量 | AD19: 種別 | AJ19: 含有成分
B25: 使用場所
B27: 保管場所 | Z27: 使用機械 又は工具
B29: 使用期間 | J29: 年 月 日 | X29: ～ | Z29: 年 月 日 | AN29: （予定）
B31: 作業主任者等 | J31: 氏 名
J32: 作業手順書 | Q32: 添付（ | AG32: ）
B33: ＳＤＳ | J33: Ｓ Ｄ Ｓ | Q33: 添付（ | AG33: ）
B35: 換気等対策
B37: （注） | E37: １．商品名、種別、含有成分等は材料に添付されているラベル成分表等から写しを記入してください。 ２．危険物とは、ガソリン、灯油、プロパン、アセチレンガス等をいいます。 ３．有害物とは、塗装、防水などに使用する有機溶剤、特定化学物質などをいいます。

Sheet 火気
B1: 参考様式第9号 | AE1: 元請 確認欄
AF3: 年 月 日
M6: 火気使用願
B8: 事業所の名称 | I8: =IF(元請入力データ!E16="","",元請入力データ!E16) -> 加賀中学校外壁改修その他工事現場事務所 | Y8: 一次会社名 | AF8: =IF(下請入力データ!E3="","",下請入力データ!E3) -> 株式会社雅
B10: 所長名 | I10: =IF(元請入力データ!E36="","",元請入力データ!E36) -> 遠藤 秀則 | T10: 殿 | Y10: 使用会社名
Y11: （ | AD11: 次 | AE11: ）
Y12: 現場代理人 | AF12: =IF(下請入力データ!E37="","",下請入力データ!E37) -> 小俣拓也
Y13: (現場責任者） | AT13: 印
G14: 下記の要領で火気を使用したく許可願います。なお、火気使用の終了時には、必ずその旨報告致します。
B16: 使用場所
B17: 使用目的 | L17: 溶接 | P17: 溶断 | T17: 圧接 | X17: 防水 | Z17: 使用期間 | AF17: 月 日 | AM17: ～ | AN17: 月 日
L18: 乾燥 | P18: 採暖 | T18: 湯沸 | X18: 炊事 | Z18: 使用時間 | AF18: 時 分 | AM18: ～ | AN18: 時 分
J19: その他（ | X19: ） | Z19: （原則）
B20: 火気の種類 | L20: 電気 | Q20: ガス | V20: 灯油 | AA20: 重油 | AF20: 木炭 | AK20: 薪
J21: その他（ | AS21: ）
B22: 管理方法 | L22: 消火器 | Q22: 消火用水 | V22: 消火砂 | AA22: 防炎シート | AF22: 受皿 | AK22: 標識 | AP22: 監視
J23: 取扱上の注意（ | AS23: ）
B24: 火元責任者
B25: (後始末巡回者）
B26: 火気使用責任者
B27: ※使用目的、火気の種類、管理方法は該当事項の□をチェックして下さい。
B31: 許可 第 号 | O31: （許可年月日） | X31: 年 月 日
B32: 火気使用許可 | O32: 防災管理者
O33: 担当係員
B34: 許可条件
B38: ※毎日時間で管理する場合は、この様式を参考にして書式を作成して下さい。
